<?xml version="1.0" encoding="utf-8"?>
<!-- =================================================================================== -->
<!-- |    This document was autogenerated by xacro from double_table_cart.urdf.xacro   | -->
<!-- |    EDITING THIS FILE BY HAND IS NOT RECOMMENDED                                 | -->
<!-- =================================================================================== -->
<robot name="DoubleTableCart" xmlns:xacro="http://www.ros.org/wiki/xacro">
  <!-- Table -->
  <link name="Foot">
    <visual>
      <geometry>
        <box size="0.35 0.122 0.01"/>
      </geometry>
      <origin rpy="0.0 0.0 0.0" xyz="0.118 0.0 0.005"/>
    </visual>
    <collision>
      <geometry>
        <sphere radius="0.005"/>
      </geometry>
      <origin rpy="0.0 0.0 0.0" xyz="-0.0285 -0.061 0.005"/>
    </collision>
    <collision>
      <geometry>
        <sphere radius="0.005"/>
      </geometry>
      <origin rpy="0.0 0.0 0.0" xyz="0.1465 -0.061 0.005"/>
    </collision>
    <collision>
      <geometry>
        <sphere radius="0.005"/>
      </geometry>
      <origin rpy="0.0 0.0 0.0" xyz="-0.0285 0.061 0.005"/>
    </collision>
    <collision>
      <geometry>
        <sphere radius="0.005"/>
      </geometry>
      <origin rpy="0.0 0.0 0.0" xyz="0.1465 0.061 0.005"/>
    </collision>
    <inertial>
      <mass value="0.0"/>
      <inertia ixx="0.0" ixy="0.0" ixz="0.0" iyy="0.0" iyz="0.0" izz="0.0"/>
      <origin rpy="0.0 0.0 0.0" xyz="0.0 0.0 0.0"/>
    </inertial>
  </link>
  <link name="TableTop">
    <visual>
      <geometry>
        <box size="1.10 1.10 0.01"/>
      </geometry>
      <origin rpy="0.0 0.0 0.0" xyz="0.0 0.0 0.721"/>
    </visual>
    <visual>
      <geometry>
        <cylinder length="0.706" radius="0.03"/>
      </geometry>
      <origin rpy="0.0 0.0 0.0" xyz="0.0 0.0 0.363"/>
    </visual>
    <inertial>
      <!-- Minimal inertia for the table to avoid numerical instabilities -->
      <mass value="1e-1"/>
      <inertia ixx="1.0e-4" ixy="1.0e-4" ixz="1.0e-4" iyy="1.0e-4" iyz="1.0e-4" izz="1.0e-4"/>
      <origin rpy="0.0 0.0 0.0" xyz="0.0 0.0 0.0"/>
    </inertial>
  </link>
  <joint name="FootTable" type="fixed">
    <origin rpy="0.0 0.0 0.0" xyz="0.0 0.0 0.0"/>
    <parent link="Foot"/>
    <child link="TableTop"/>
  </joint>
  <!-- Robot -->
  <link name="RobotCart">
    <visual>
      <geometry>
        <box size="0.10 0.10 0.04"/>
      </geometry>
      <material name="red">
        <color rgba="0.9 0.0 0.0 1"/>
      </material>
      <origin rpy="0.0 0.0 0.0" xyz="0.0 0.0 0.025"/>
    </visual>
    <inertial>
      <mass value="74.8"/>
      <inertia ixx="13.257" ixy="0.064" ixz="1.283" iyy="11.849" iyz="-0.095" izz="3.343"/>
      <origin rpy="0.0 0.0 0.0" xyz="0.0 0.0 0.0"/>
    </inertial>
  </link>
  <joint name="RobotStrapsToPatient" type="fixed">
    <origin rpy="0.0 0.0 0.0" xyz="0.004 0.0 0.0"/>
    <parent link="RobotCart"/>
    <child link="RobotStraps"/>
  </joint>
  <link name="RobotStraps"/>
  <link name="RobotPlanarJoint"/>
  <joint name="TableTopToRobotCartX" type="prismatic">
    <origin rpy="0.0 0.0 0.0" xyz="0.0 0.0 0.721"/>
    <axis xyz="1 0 0"/>
    <parent link="TableTop"/>
    <child link="RobotPlanarJoint"/>
    <limit effort="2680.0" lower="-0.5" upper="0.5" velocity="2.23"/>
  </joint>
  <joint name="TableTopToRobotCartY" type="prismatic">
    <origin rpy="0.0 0.0 0.0" xyz="0.0 0.0 0.0"/>
    <axis xyz="0 1 0"/>
    <parent link="RobotPlanarJoint"/>
    <child link="RobotCart"/>
    <limit effort="1640.0" lower="-0.5" upper="0.5" velocity="0.79"/>
  </joint>
  <!-- Patient lower body -->
  <link name="PatientLowerBodyCart">
    <visual>
      <geometry>
        <box size="0.10 0.10 0.04"/>
      </geometry>
      <material name="green">
        <color rgba="0.0 0.9 0.0 1"/>
      </material>
      <origin rpy="0.0 0.0 0.0" xyz="0.0 0.0 0.025"/>
    </visual>
    <visual>
      <geometry>
        <cylinder length="0.158" radius="0.015"/>
      </geometry>
      <material name="green">
        <color rgba="0.0 0.9 0.0 1"/>
      </material>
      <origin rpy="0.0 0.0 0.0" xyz="0.0 0.0 0.1215"/>
    </visual>
    <visual>
      <geometry>
        <box size="0.301 0.224 0.01"/>
      </geometry>
      <material name="green">
        <color rgba="0.0 0.9 0.0 1"/>
      </material>
      <origin rpy="0.0 0.0 0.0" xyz="0.0645 0.0 0.203"/>
    </visual>
    <inertial>
      <mass value="32.6"/>
      <inertia ixx="3.57" ixy="0.0" ixz="0.11" iyy="3.345" iyz="0.0" izz="0.328"/>
      <origin rpy="0.0 0.0 0.0" xyz="0.0 0.0 0.0"/>
    </inertial>
  </link>
  <link name="PatientLowerBodyPlanarJoint"/>
  <joint name="TableTopToPatientLowerBodyCartX" type="prismatic">
    <origin rpy="0.0 0.0 0.0" xyz="0.0 0.0 0.721"/>
    <axis xyz="1 0 0"/>
    <parent link="TableTop"/>
    <child link="PatientLowerBodyPlanarJoint"/>
    <limit effort="1000.0" lower="-0.5" upper="0.5" velocity="100.0"/>
  </joint>
  <joint name="TableTopToPatientLowerBodyCartY" type="prismatic">
    <origin rpy="0.0 0.0 0.0" xyz="0.0 0.0 0.0"/>
    <axis xyz="0 1 0"/>
    <parent link="PatientLowerBodyPlanarJoint"/>
    <child link="PatientLowerBodyCart"/>
    <limit effort="1000.0" lower="-0.5" upper="0.5" velocity="100.0"/>
  </joint>
  <!-- Patient upper body -->
  <link name="PatientUpperBodyCart">
    <visual>
      <geometry>
        <box size="0.10 0.10 0.04"/>
      </geometry>
      <material name="blue">
        <color rgba="0.0 0.0 0.9 1"/>
      </material>
      <origin rpy="0.0 0.0 0.0" xyz="0.0 0.0 0.025"/>
    </visual>
    <inertial>
      <mass value="42.8"/>
      <inertia ixx="3.418" ixy="0.0" ixz="-0.003" iyy="0.886" iyz="0.0" izz="2.651"/>
      <origin rpy="0.0 0.0 0.0" xyz="0.0 0.0 0.0"/>
    </inertial>
  </link>
  <link name="PatientUpperBodyPlanarJoint"/>
  <joint name="PatientLowerBodyToPatientUpperBodyCartX" type="prismatic">
    <origin rpy="0.0 0.0 0.0" xyz="0.0 0.0 0.203"/>
    <axis xyz="1 0 0"/>
    <parent link="PatientLowerBodyCart"/>
    <child link="PatientUpperBodyPlanarJoint"/>
    <limit effort="200.0" lower="-0.036" upper="0.165" velocity="3.0"/>
  </joint>
  <joint name="PatientLowerBodyToPatientUpperBodyCartY" type="prismatic">
    <origin rpy="0.0 0.0 0.0" xyz="0.0 0.0 0.0"/>
    <axis xyz="0 1 0"/>
    <parent link="PatientUpperBodyPlanarJoint"/>
    <child link="PatientUpperBodyCart"/>
    <limit effort="300.0" lower="-0.062" upper="0.062" velocity="1.0"/>
  </joint>
</robot>

