<?xml version="1.0" ?>
<!-- A simple, downward-facing pendulum-->
<robot name="pendulum">
    <link name="world">
        <!-- It is necessary to add a mass to the world to work with and without freeflyer. -->
        <inertial>
            <origin xyz="0.0 0.0 0.0" rpy="0.0 0.0 0.0"/>
            <mass value="42.0"/>
            <inertia ixx="42.0" ixy="42.0" ixz="42.0" iyy="42.0" iyz="42.0" izz="42.0"/>
        </inertial>
    </link>
    <joint name="PendulumJoint" type="revolute">
      <origin xyz="0.0 0.0 0.0" rpy="0 0 0"/>
      <axis xyz="0 1 0"/>
      <parent link="world"/>
      <child link="PendulumArm"/>
      <limit effort="1000" velocity="100" lower="-1.5" upper="1.5"/>
    </joint>
    <link name="PendulumArm">
        <inertial>
            <origin xyz="0.0 0.0 0.0" rpy="0.0 0.0 0.0"/>
            <mass value="0.0"/>
            <inertia ixx="0.0" ixy="0.0" ixz="0.0" iyy="0.0" iyz="0.0" izz="0.0"/>
        </inertial>
    </link>
    <joint name="PendulumLinkJoint" type="fixed">
      <origin xyz="0.0 0.0 -1.0" rpy="0.0 0.0 0.0"/>
      <parent link="PendulumArm"/>
      <child link="PendulumLink"/>
    </joint>
    <link name="PendulumLink">
        <inertial>
            <origin xyz="0.0 0.0 0.0" rpy="0.0 0.0 0.0"/>
            <mass value="5.0"/>
            <inertia ixx="1.0" ixy="0.0" ixz="0.0" iyy="0.0" iyz="0.0" izz="1.0"/>
        </inertial>
    </link>
</robot>
