<?xml version="1.0" ?>
<robot name="pendulum">
    <link name="base"/>

    <joint name="PendulumJoint" type="continuous">
      <origin xyz="0.0 0.0 0.0" rpy="0.0 0.0 0.0"/>
      <axis xyz="1 0 0"/>
      <parent link="base"/>
      <child link="PendulumArm"/>
      <limit effort="20.0" velocity="100.0"/>
    </joint>

    <link name="PendulumArm">
        <visual>
            <origin xyz="0.0 0.0 0.5" rpy="0.0 0.0 0.0" />
            <geometry>
                <box size="0.01 0.01 1.0"/>
            </geometry>
            <material name="">
                <color rgba="0.0 0.0 1.0 1.0"/>
            </material>
        </visual>
        <inertial>
            <origin xyz="0.0 0.0 0.0" rpy="0.0 0.0 0.0"/>
            <mass value="0.0"/>
            <inertia ixx="0.0" ixy="0.0" ixz="0.0" iyy="0.0" iyz="0.0" izz="0.0"/>
        </inertial>
    </link>

    <joint name="PendulumMassJoint" type="fixed">
      <origin xyz="0.0 0.0 1.0" rpy="0.0 0.0 0.0"/>
      <parent link="PendulumArm"/>
      <child link="PendulumMass"/>
    </joint>
    <link name="PendulumMass">
        <visual>
            <origin xyz="0.0 0.0 0.0" rpy="0.0 0.0 0.0" />
            <geometry>
                <sphere radius="0.06"/>
            </geometry>
            <material name="">
                <color rgba="0.0 0.0 1.0 1.0"/>
            </material>
        </visual>
        <inertial>
            <origin xyz="0.0 0.0 0.0" rpy="0.0 0.0 0.0"/>
            <mass value="1.0"/>
            <inertia ixx="0.0" ixy="0.0" ixz="0.0" iyy="0.0" iyz="0.0" izz="0.0"/>
        </inertial>
    </link>
</robot>