<!-- This URDF describes a punctual mass moving along a single axis: it is
meant to unit test the interaction between two sysmtes in Jiminy.
-->
<?xml version="1.0" ?>
<robot name="linear_mass">
    <link name="world"/>
    <joint name="Joint" type="prismatic">
      <origin xyz="0.0 0.0 0.0" rpy="0 0 0"/>
      <axis xyz="1 0 0"/>
      <parent link="world"/>
      <child link="Mass"/>
      <limit effort="1000" velocity="0" lower="-1000" upper="1000"/>
    </joint>
    <link name="Mass">
        <inertial>
            <origin xyz="0.0 0.0 0.0" rpy="0.0 0.0 0.0"/>
            <mass value="1.0"/>
            <inertia ixx="0.0" ixy="0.0" ixz="0.0" iyy="0.0" iyz="0.0" izz="0.0"/>
        </inertial>
    </link>
</robot>
