<!-- A simple, doward-facing pendulum-->
<?xml version="1.0" ?>
<robot name="pendulum">
    <link name="world"/>
    <joint name="PendulumJoint" type="revolute">
      <origin xyz="0.0 0.0 0.0" rpy="0 0 0"/>
      <axis xyz="0 1 0"/>
      <parent link="world"/>
      <child link="PendulumLink"/>
      <limit effort="1000" velocity="100" lower="-1.5" upper="1.5"/>
    </joint>
    <link name="PendulumLink">
        <inertial>
            <origin xyz="0.0 0.0 -1.0" rpy="0.0 0.0 0.0"/>
            <mass value="1.0"/>
            <inertia ixx="0.0" ixy="0.0" ixz="0.0" iyy="0.0" iyz="0.0" izz="0.0"/>
        </inertial>
    </link>
</robot>
