<?xml version="1.0"?>
<robot name="physics">

    <link name="slideBar">
    <visual>
      <geometry>
        <mesh filename="package://cart_two_poles/slideBar.STL"/>
        <!-- <box size="30 0.05 0.05"/> -->
      </geometry>
      <origin xyz="0 0 0"/>
      <material name="green">
        <color rgba="0 0.8 .8 1"/>
      </material>
    </visual>
    <inertial>
      <mass value="0"/>
      <inertia ixx="1.0" ixy="0.0" ixz="0.0" iyy="1.0" iyz="0.0" izz="1.0"/>
    </inertial>
  </link>

  <link name="cart">
    <visual>
      <geometry>
        <mesh filename="package://cart_two_poles/cart.STL"/>
        <!-- <box size="0.5 0.5 0.2"/> -->
      </geometry>
      <origin xyz="0 0 0"/>
      <material name="blue">
        <color rgba="0 0 .8 1"/>
      </material>
    </visual>
    <collision>
      <geometry>
        <mesh filename="package://cart_two_poles/cart.STL"/>
          <!-- <box size="0.5 0.5 0.2"/> -->
      </geometry>
      <origin xyz="0 0 0"/>
    </collision>
    <inertial>
      <mass value="1"/>
      <inertia ixx="1.0" ixy="0.0" ixz="0.0" iyy="1.0" iyz="0.0" izz="1.0"/>
    </inertial>
  </link>

  <joint name="slider_to_cart" type="prismatic">
    <axis xyz="1 0 0"/>
    <origin xyz="0.0 0.0 0.0"/>
    <parent link="slideBar"/>
    <child link="cart"/>
    <limit effort="1000.0" lower="-15" upper="15" velocity="5"/>
  </joint>

  <link name="pole1">
    <visual>
      <geometry>
        <mesh filename="package://cart_two_poles/pole1.STL"/>
        <!-- <box size="0.05 0.05 1.0"/>	 -->
      </geometry>
      <origin rpy="0.0 0.0 0.0" xyz="0.0 -0.05 0.5"/>
      <material name="white">
        <color rgba="1 1 1 1"/>
      </material>
    </visual>
    <inertial>
    <origin xyz="0.0 -0.05 0.5"/>
      <mass value="10"/>
      <inertia ixx="1.0" ixy="0.0" ixz="0.0" iyy="1.0" iyz="0.0" izz="1.0"/>
    </inertial>
     <collision>
      <geometry>
        <mesh filename="package://cart_two_poles/pole1.STL"/>
        <!-- <box size="0.05 0.05 1.0"/>	 -->
      </geometry>
      <origin rpy="0.0 0.0 0.0" xyz="0.0 -0.05 0.5"/>
    </collision>
  </link>

  <joint name="cart_to_pole1" type="revolute">
    <axis xyz="0 1 0"/>
    <origin xyz="0.0 0.0 0.0" rpy="0.0 0.0 0.0"/>
    <parent link="cart"/>
    <child link="pole1"/>
    <limit effort="1000.0" lower="-15" upper="15" velocity="5"/>
  </joint>

  <link name="pole2">
    <visual>
      <geometry>
        <mesh filename="package://cart_two_poles/pole2.STL"/>
        <!-- <box size="0.05 0.05 1.6"/>	 -->
      </geometry>
      <origin rpy="0.0 0.0 0.0" xyz="0.0 0.05 0.8"/>
      <material name="white">
        <color rgba="1 0 0 1"/>
      </material>
    </visual>
    <inertial>
    <origin xyz="0.0 0.05 0.8"/>
      <mass value="3"/>
      <inertia ixx="2.3" ixy="0.0" ixz="0.0" iyy="2.3" iyz="0.0" izz="2.3"/>
    </inertial>
     <collision>
      <geometry>
        <mesh filename="package://cart_two_poles/pole2.STL"/>
        <!-- <box size="0.05 0.05 1.6"/>	 -->
      </geometry>
      <origin rpy="0.0 0.0 0.0" xyz="0.0 0.05 0.8"/>
    </collision>
  </link>

  <joint name="cart_to_pole2" type="revolute">
    <axis xyz="0 1 0"/>
    <origin xyz="0.0 0.0 0.0" rpy="0.0 0.0 0.0"/>
    <parent link="cart"/>
    <child link="pole2"/>
    <limit effort="1000.0" lower="-15" upper="15" velocity="5"/>
  </joint>

</robot>
